Workbook
Name _ftn1: 'Power Plants'!#REF!
Name _ftnref1: 'Power Plants'!$B$6
Name _Ref171844817: 'Power Plants'!$B$6

Sheet Supply Risk
A1: WGI | B1: Interactive Data Access | Worldwide Governance Indicators | F1: Inputs
A2: Data on suppliers | B2: CRMS 2023 - SCRREEN3 | F2: Assumptions
A4: Global | I4: Concentration score (global supply)
A5: Country | B5: Share | C5: HHI contrib | D5: WGI | E5: WGI scaled | F5: tc | G5: HHI_WGI_t contrib | I5: (HHIWGI-tc)GS | K5: IR | L5: (HHIWGI-tc)GS | M5: Sourcing global, IR weighted | N5: (HHIWGI-tc)EU | O5: Sourcing EU, IR weighted | P5: EoL-RIR | Q5: SISR | R5: SR Score
A6: Chile | B6: 0.32 | C6: =(B6*100)^2 -> 1024 | D6: 0.5 | E6: =10-(D6+2.5)*2 -> 4 | F6: 1 | G6: =C6*E6*F6 -> 4096 | I6: =SUM(G6:G15)/10000 -> 2.36138 | K6: 1 | L6: =I6 -> 2.36138 | M6: =L6*K6/2 -> 1.18069 | N6: =I19 -> 2.54052 | O6: =N6*(1-K6/2) -> 1.27026 | P6: 0.01 | Q6: 1 | R6: =(M6+O6)*(1-P6)*Q6 -> 2.4264405
A7: China | B7: 0.56 | C7: =(B7*100)^2 -> 3136 | D7: -0.5 | E7: =10-(D7+2.5)*2 -> 6 | F7: 1 | G7: =C7*E7*F7 -> 18816
A8: Argentina | B8: 0.11 | C8: =(B8*100)^2 -> 121 | D8: -0.4 | E8: =10-(D8+2.5)*2 -> 5.8 | F8: 1 | G8: =C8*E8*F8 -> 701.8
C9: =(B9*100)^2 -> 0 | E9: =10-(D9+2.5)*2 -> 5 | F9: 1 | G9: =C9*E9*F9 -> 0
C10: =(B10*100)^2 -> 0 | E10: =10-(D10+2.5)*2 -> 5 | F10: 1 | G10: =C10*E10*F10 -> 0
C11: =(B11*100)^2 -> 0 | E11: =10-(D11+2.5)*2 -> 5 | F11: 1 | G11: =C11*E11*F11 -> 0
C12: =(B12*100)^2 -> 0 | E12: =10-(D12+2.5)*2 -> 5 | F12: 1 | G12: =C12*E12*F12 -> 0
C13: =(B13*100)^2 -> 0 | E13: =10-(D13+2.5)*2 -> 5 | F13: 1 | G13: =C13*E13*F13 -> 0
C14: =(B14*100)^2 -> 0 | E14: =10-(D14+2.5)*2 -> 5 | F14: 1 | G14: =C14*E14*F14 -> 0
C15: =(B15*100)^2 -> 0 | E15: =10-(D15+2.5)*2 -> 5 | F15: 1 | G15: =C15*E15*F15 -> 0
A17: EU | I17: Concentration score (EU supply)
A18: Country | B18: Share | C18: HHI contrib | D18: WGI | E18: WGI scaled | F18: tc | G18: HHI_WGI_t contrib | I18: (HHIWGI-tc)EU
A19: Chile | B19: 0.79 | C19: =(B19*100)^2 -> 6241 | D19: 0.5 | E19: =10-(D19+2.5)*2 -> 4 | F19: 1 | G19: =C19*E19*F19 -> 24964 | I19: =SUM(G19:G28)/10000 -> 2.54052
A20: Switzerland | B20: 0.07 | C20: =(B20*100)^2 -> 49 | D20: 2 | E20: =10-(D20+2.5)*2 -> 1 | F20: 1 | G20: =C20*E20*F20 -> 49
A21: Argentina | B21: 0.07 | C21: =(B21*100)^2 -> 49 | D21: -0.4 | E21: =10-(D21+2.5)*2 -> 5.8 | F21: 1 | G21: =C21*E21*F21 -> 284.2
A22: USA | B22: 0.06 | C22: =(B22*100)^2 -> 36 | D22: 1 | E22: =10-(D22+2.5)*2 -> 3 | F22: 1 | G22: =C22*E22*F22 -> 108
C23: =(B23*100)^2 -> 0 | E23: =10-(D23+2.5)*2 -> 5 | F23: 1 | G23: =C23*E23*F23 -> 0
C24: =(B24*100)^2 -> 0 | E24: =10-(D24+2.5)*2 -> 5 | F24: 1 | G24: =C24*E24*F24 -> 0
C25: =(B25*100)^2 -> 0 | E25: =10-(D25+2.5)*2 -> 5 | F25: 1 | G25: =C25*E25*F25 -> 0
C26: =(B26*100)^2 -> 0 | E26: =10-(D26+2.5)*2 -> 5 | F26: 1 | G26: =C26*E26*F26 -> 0
C27: =(B27*100)^2 -> 0 | E27: =10-(D27+2.5)*2 -> 5 | F27: 1 | G27: =C27*E27*F27 -> 0
C28: =(B28*100)^2 -> 0 | E28: =10-(D28+2.5)*2 -> 5 | F28: 1 | G28: =C28*E28*F28 -> 0

Sheet Raw Materials
A1: Material | C1: Supply Risk | D1: Global Consumption (t)
A2: Aluminium | B2: ALU | C2: 1.2 | D2: 70000000
A3: Boron | B3: BOR | C3: 3.8 | D3: 4500000
A4: Cerium | B4: CER | C4: 4 | D4: 150000
A5: Chromium | B5: CHR | C5: 0.7 | D5: 40000000
A6: Cobalt | B6: COB | C6: 1.7 | D6: 220000
A7: Copper | B7: COP | C7: 0.1 | D7: 26000000
A8: Dysprosium | B8: DYS | C8: 5.6 | D8: 2500
A9: Europium | B9: EUP | C9: 5.6 | D9: 500
A10: Fluorspar | B10: FLU | C10: 1.1 | D10: 7500000
A11: Gadolinium | B11: GAD | C11: 3.3 | D11: 2000
A12: Gallium | B12: GAL | C12: 4.8 | D12: 420
A13: Germanium | B13: GER | C13: 1.8 | D13: 170
... A36: Zirconium | B36: ZIR | C36: 0.8 | D36: 1400000

Sheet Cars
A1: Technology | B1: Material Consumption | D1: MI_m | E1: SR(MI_1) | F1: MI_m*SR_m | G1: SR(MI_2) | H1: MI_m*SR_m/cons_m | I1: SR(cons)
C2: kg/vehicle | D2: t/kvehicles
A3: Internal Combustion Engines | B3: COP | C3: 31.258425 | D3: =C3 -> 31.258425 | E3: =SUM(D3:D4) -> 46.95768 | F3: {=$D3*SUM(IF('Raw Materials'!$B$2:$B$36=Cars!$B3,'Raw Materials'!$C$2:$C$36))} -> 3.1258425 | G3: =SUM(F3:F4) -> 21.964948 | H3: {=$D3*SUM(IF('Raw Materials'!$B$2:$B$36=$B3,'Raw Materials'!$C$2:$C$36))/SUM(IF('Raw Materials'!$B$2:$B$36=Cars!$B3,'Raw Materials'!$D$2:$D$36))} -> 1.2022471e-07 | I3: =SUM(H3:H4) -> 1.06218e-06
B4: MAN | C4: 15.699255 | D4: =C4 -> 15.699255 | F4: {=$D4*SUM(IF('Raw Materials'!$B$2:$B$36=Cars!$B4,'Raw Materials'!$C$2:$C$36))} -> 18.839106 | H4: {=$D4*SUM(IF('Raw Materials'!$B$2:$B$36=$B4,'Raw Materials'!$C$2:$C$36))/SUM(IF('Raw Materials'!$B$2:$B$36=Cars!$B4,'Raw Materials'!$D$2:$D$36))} -> 9.419553e-07
A5: Battery Electric Vehicles | B5: CER | C5: 0.000165 | D5: =C5 -> 0.000165 | E5: =SUM(D5:D30) -> 308.54257 | F5: {=$D5*SUM(IF('Raw Materials'!$B$2:$B$36=Cars!$B5,'Raw Materials'!$C$2:$C$36))} -> 0.00066 | G5: =SUM(F5:F30) -> 247.72664 | H5: {=$D5*SUM(IF('Raw Materials'!$B$2:$B$36=$B5,'Raw Materials'!$C$2:$C$36))/SUM(IF('Raw Materials'!$B$2:$B$36=Cars!$B5,'Raw Materials'!$D$2:$D$36))} -> 4.4e-09 | I5: =SUM(H5:H30) -> 0.0012765043
B6: CHR | C6: 13.89102 | D6: =C6 -> 13.89102 | F6: {=$D6*SUM(IF('Raw Materials'!$B$2:$B$36=Cars!$B6,'Raw Materials'!$C$2:$C$36))} -> 9.723714 | H6: {=$D6*SUM(IF('Raw Materials'!$B$2:$B$36=$B6,'Raw Materials'!$C$2:$C$36))/SUM(IF('Raw Materials'!$B$2:$B$36=Cars!$B6,'Raw Materials'!$D$2:$D$36))} -> 2.4309285e-07
B7: COB | C7: 18.642855 | D7: =C7 -> 18.642855 | F7: {=$D7*SUM(IF('Raw Materials'!$B$2:$B$36=Cars!$B7,'Raw Materials'!$C$2:$C$36))} -> 31.692853 | H7: {=$D7*SUM(IF('Raw Materials'!$B$2:$B$36=$B7,'Raw Materials'!$C$2:$C$36))/SUM(IF('Raw Materials'!$B$2:$B$36=Cars!$B7,'Raw Materials'!$D$2:$D$36))} -> 0.00014405842
B8: COP | C8: 74.571585 | D8: =C8 -> 74.571585 | F8: {=$D8*SUM(IF('Raw Materials'!$B$2:$B$36=Cars!$B8,'Raw Materials'!$C$2:$C$36))} -> 7.4571585 | H8: {=$D8*SUM(IF('Raw Materials'!$B$2:$B$36=$B8,'Raw Materials'!$C$2:$C$36))/SUM(IF('Raw Materials'!$B$2:$B$36=Cars!$B8,'Raw Materials'!$D$2:$D$36))} -> 2.8681379e-07
B9: DYS | C9: 0.22572 | D9: =C9 -> 0.22572 | F9: {=$D9*SUM(IF('Raw Materials'!$B$2:$B$36=Cars!$B9,'Raw Materials'!$C$2:$C$36))} -> 1.264032 | H9: {=$D9*SUM(IF('Raw Materials'!$B$2:$B$36=$B9,'Raw Materials'!$C$2:$C$36))/SUM(IF('Raw Materials'!$B$2:$B$36=Cars!$B9,'Raw Materials'!$D$2:$D$36))} -> 0.0005056128
B10: EUP | C10: 0.00033 | D10: =C10 -> 0.00033 | F10: {=$D10*SUM(IF('Raw Materials'!$B$2:$B$36=Cars!$B10,'Raw Materials'!$C$2:$C$36))} -> 0.001848 | H10: {=$D10*SUM(IF('Raw Materials'!$B$2:$B$36=$B10,'Raw Materials'!$C$2:$C$36))/SUM(IF('Raw Materials'!$B$2:$B$36=Cars!$B10,'Raw Materials'!$D$2:$D$36))} -> 3.696e-06
B11: GAD | C11: 0.000165 | D11: =C11 -> 0.000165 | F11: {=$D11*SUM(IF('Raw Materials'!$B$2:$B$36=Cars!$B11,'Raw Materials'!$C$2:$C$36))} -> 0.0005445 | H11: {=$D11*SUM(IF('Raw Materials'!$B$2:$B$36=$B11,'Raw Materials'!$C$2:$C$36))/SUM(IF('Raw Materials'!$B$2:$B$36=Cars!$B11,'Raw Materials'!$D$2:$D$36))} -> 2.7225e-07
B12: GAL | C12: 0.00132 | D12: =C12 -> 0.00132 | F12: {=$D12*SUM(IF('Raw Materials'!$B$2:$B$36=Cars!$B12,'Raw Materials'!$C$2:$C$36))} -> 0.006336 | H12: {=$D12*SUM(IF('Raw Materials'!$B$2:$B$36=$B12,'Raw Materials'!$C$2:$C$36))/SUM(IF('Raw Materials'!$B$2:$B$36=Cars!$B12,'Raw Materials'!$D$2:$D$36))} -> 1.5085714e-05
B13: GER | C13: 0.000165 | D13: =C13 -> 0.000165 | F13: {=$D13*SUM(IF('Raw Materials'!$B$2:$B$36=Cars!$B13,'Raw Materials'!$C$2:$C$36))} -> 0.000297 | H13: {=$D13*SUM(IF('Raw Materials'!$B$2:$B$36=$B13,'Raw Materials'!$C$2:$C$36))/SUM(IF('Raw Materials'!$B$2:$B$36=Cars!$B13,'Raw Materials'!$D$2:$D$36))} -> 1.7470588e-06
B14: GRA | C14: 92.934105 | D14: =C14 -> 92.934105 | F14: {=$D14*SUM(IF('Raw Materials'!$B$2:$B$36=Cars!$B14,'Raw Materials'!$C$2:$C$36))} -> 92.934105 | H14: {=$D14*SUM(IF('Raw Materials'!$B$2:$B$36=$B14,'Raw Materials'!$C$2:$C$36))/SUM(IF('Raw Materials'!$B$2:$B$36=Cars!$B14,'Raw Materials'!$D$2:$D$36))} -> 2.3233526e-05
B15: IND | C15: 0.00033 | D15: =C15 -> 0.00033 | F15: {=$D15*SUM(IF('Raw Materials'!$B$2:$B$36=Cars!$B15,'Raw Materials'!$C$2:$C$36))} -> 0.000198 | H15: {=$D15*SUM(IF('Raw Materials'!$B$2:$B$36=$B15,'Raw Materials'!$C$2:$C$36))/SUM(IF('Raw Materials'!$B$2:$B$36=Cars!$B15,'Raw Materials'!$D$2:$D$36))} -> 2.3294118e-07
B16: LAN | C16: 0.009735 | D16: =C16 -> 0.009735 | F16: {=$D16*SUM(IF('Raw Materials'!$B$2:$B$36=Cars!$B16,'Raw Materials'!$C$2:$C$36))} -> 0.0340725 | H16: {=$D16*SUM(IF('Raw Materials'!$B$2:$B$36=$B16,'Raw Materials'!$C$2:$C$36))/SUM(IF('Raw Materials'!$B$2:$B$36=Cars!$B16,'Raw Materials'!$D$2:$D$36))} -> 6.8145e-07
B17: LIT | C17: 12.47532 | D17: =C17 -> 12.47532 | F17: {=$D17*SUM(IF('Raw Materials'!$B$2:$B$36=Cars!$B17,'Raw Materials'!$C$2:$C$36))} -> 23.703108 | H17: {=$D17*SUM(IF('Raw Materials'!$B$2:$B$36=$B17,'Raw Materials'!$C$2:$C$36))/SUM(IF('Raw Materials'!$B$2:$B$36=Cars!$B17,'Raw Materials'!$D$2:$D$36))} -> 2.6336787e-05
... B30: YTT | C30: 0.000495 | D30: =C30 -> 0.000495 | F30: {=$D30*SUM(IF('Raw Materials'!$B$2:$B$36=Cars!$B30,'Raw Materials'!$C$2:$C$36))} -> 0.0017325 | H30: {=$D30*SUM(IF('Raw Materials'!$B$2:$B$36=$B30,'Raw Materials'!$C$2:$C$36))/SUM(IF('Raw Materials'!$B$2:$B$36=Cars!$B30,'Raw Materials'!$D$2:$D$36))} -> 1.575e-07

Sheet Power Plants
A1: Technology | B1: Material Consumption | D1: MI_m | E1: SR(MI_1) | F1: MI_m*SR_m | G1: SR(MI_2) | H1: MI_m*SR_m/cons_m | I1: SR(cons)
C2: kg/MW | D2: t/cap
A3: PV | B3: ALU | C3: 7500 | D3: =C3 -> 7500 | E3: =SUM(D3:D8) -> 12105.89 | F3: {=$D3*SUM(IF('Raw Materials'!$B$2:$B$36=$B3,'Raw Materials'!$C$2:$C$36))} -> 9000 | G3: =SUM(F3:F8) -> 9467.122 | H3: {=$D3*SUM(IF('Raw Materials'!$B$2:$B$36=$B3,'Raw Materials'!$C$2:$C$36))/SUM(IF('Raw Materials'!$B$2:$B$36=$B3,'Raw Materials'!$D$2:$D$36))} -> 0.00012857143 | I3: =SUM(H3:H8) -> 0.00076614524
B4: COP | C4: 4600 | D4: =C4 -> 4600 | F4: {=$D4*SUM(IF('Raw Materials'!$B$2:$B$36=$B4,'Raw Materials'!$C$2:$C$36))} -> 460 | H4: {=$D4*SUM(IF('Raw Materials'!$B$2:$B$36=$B4,'Raw Materials'!$C$2:$C$36))/SUM(IF('Raw Materials'!$B$2:$B$36=$B4,'Raw Materials'!$D$2:$D$36))} -> 1.7692308e-05
B5: GAL | C5: 0.04 | D5: =C5 -> 0.04 | F5: {=$D5*SUM(IF('Raw Materials'!$B$2:$B$36=$B5,'Raw Materials'!$C$2:$C$36))} -> 0.192 | H5: {=$D5*SUM(IF('Raw Materials'!$B$2:$B$36=$B5,'Raw Materials'!$C$2:$C$36))/SUM(IF('Raw Materials'!$B$2:$B$36=$B5,'Raw Materials'!$D$2:$D$36))} -> 0.00045714286
B6: IND | C6: 0.15 | D6: =C6 -> 0.15 | F6: {=$D6*SUM(IF('Raw Materials'!$B$2:$B$36=$B6,'Raw Materials'!$C$2:$C$36))} -> 0.09 | H6: {=$D6*SUM(IF('Raw Materials'!$B$2:$B$36=$B6,'Raw Materials'!$C$2:$C$36))/SUM(IF('Raw Materials'!$B$2:$B$36=$B6,'Raw Materials'!$D$2:$D$36))} -> 0.00010588235
B7: SIL | C7: 3.8 | D7: =C7 -> 3.8 | F7: {=$D7*SUM(IF('Raw Materials'!$B$2:$B$36=$B7,'Raw Materials'!$C$2:$C$36))} -> 5.32 | H7: {=$D7*SUM(IF('Raw Materials'!$B$2:$B$36=$B7,'Raw Materials'!$C$2:$C$36))/SUM(IF('Raw Materials'!$B$2:$B$36=$B7,'Raw Materials'!$D$2:$D$36))} -> 5.6e-07 | L7: Solar PV | M7: =I3 -> 0.00076614524
B8: SIV | C8: 1.9 | D8: =C8 -> 1.9 | F8: {=$D8*SUM(IF('Raw Materials'!$B$2:$B$36=$B8,'Raw Materials'!$C$2:$C$36))} -> 1.52 | H8: {=$D8*SUM(IF('Raw Materials'!$B$2:$B$36=$B8,'Raw Materials'!$C$2:$C$36))/SUM(IF('Raw Materials'!$B$2:$B$36=$B8,'Raw Materials'!$D$2:$D$36))} -> 5.6296296e-05 | L8: Wind | M8: =I9 -> 0.028829183
A9: Wind | B9: ALU | C9: 1250 | D9: =C9 -> 1250 | E9: =SUM(D9:D19) -> 4881.06 | F9: {=$D9*SUM(IF('Raw Materials'!$B$2:$B$36=$B9,'Raw Materials'!$C$2:$C$36))} -> 1500 | G9: =SUM(F9:F19) -> 3446.93 | H9: {=$D9*SUM(IF('Raw Materials'!$B$2:$B$36=$B9,'Raw Materials'!$C$2:$C$36))/SUM(IF('Raw Materials'!$B$2:$B$36=$B9,'Raw Materials'!$D$2:$D$36))} -> 2.1428571e-05 | I9: =SUM(H9:H19) -> 0.028829183 | L9: Hydropower | M9: =I20 -> 2.0450226e-05
B10: BOR | C10: 0.94 | D10: =C10 -> 0.94 | F10: {=$D10*SUM(IF('Raw Materials'!$B$2:$B$36=$B10,'Raw Materials'!$C$2:$C$36))} -> 3.572 | H10: {=$D10*SUM(IF('Raw Materials'!$B$2:$B$36=$B10,'Raw Materials'!$C$2:$C$36))/SUM(IF('Raw Materials'!$B$2:$B$36=$B10,'Raw Materials'!$D$2:$D$36))} -> 7.9377778e-07 | L10: Bioenergy | M10: =I25 -> 0.00091782168
B11: CHR | C11: 492 | D11: =C11 -> 492 | F11: {=$D11*SUM(IF('Raw Materials'!$B$2:$B$36=$B11,'Raw Materials'!$C$2:$C$36))} -> 344.4 | H11: {=$D11*SUM(IF('Raw Materials'!$B$2:$B$36=$B11,'Raw Materials'!$C$2:$C$36))/SUM(IF('Raw Materials'!$B$2:$B$36=$B11,'Raw Materials'!$D$2:$D$36))} -> 8.61e-06 | L11: Coal | M11: =I27 -> 0.0018535516
B12: COP | C12: 1800 | D12: =C12 -> 1800 | F12: {=$D12*SUM(IF('Raw Materials'!$B$2:$B$36=$B12,'Raw Materials'!$C$2:$C$36))} -> 180 | H12: {=$D12*SUM(IF('Raw Materials'!$B$2:$B$36=$B12,'Raw Materials'!$C$2:$C$36))/SUM(IF('Raw Materials'!$B$2:$B$36=$B12,'Raw Materials'!$D$2:$D$36))} -> 6.9230769e-06 | L12: Natural gas & Oil | M12: =I32 -> 7.3995486e-06
B13: DYS | C13: 4.74 | D13: =C13 -> 4.74 | F13: {=$D13*SUM(IF('Raw Materials'!$B$2:$B$36=$B13,'Raw Materials'!$C$2:$C$36))} -> 26.544 | H13: {=$D13*SUM(IF('Raw Materials'!$B$2:$B$36=$B13,'Raw Materials'!$C$2:$C$36))/SUM(IF('Raw Materials'!$B$2:$B$36=$B13,'Raw Materials'!$D$2:$D$36))} -> 0.0106176 | L13: Nuclear | M13: =I35 -> 0.0045077616
B14: MAN | C14: 784 | D14: =C14 -> 784 | F14: {=$D14*SUM(IF('Raw Materials'!$B$2:$B$36=$B14,'Raw Materials'!$C$2:$C$36))} -> 940.8 | H14: {=$D14*SUM(IF('Raw Materials'!$B$2:$B$36=$B14,'Raw Materials'!$C$2:$C$36))/SUM(IF('Raw Materials'!$B$2:$B$36=$B14,'Raw Materials'!$D$2:$D$36))} -> 4.704e-05
B15: MOL | C15: 103 | D15: =C15 -> 103 | F15: {=$D15*SUM(IF('Raw Materials'!$B$2:$B$36=$B15,'Raw Materials'!$C$2:$C$36))} -> 82.4 | H15: {=$D15*SUM(IF('Raw Materials'!$B$2:$B$36=$B15,'Raw Materials'!$C$2:$C$36))/SUM(IF('Raw Materials'!$B$2:$B$36=$B15,'Raw Materials'!$D$2:$D$36))} -> 0.00027466667
B16: NEO | C16: 40.4 | D16: =C16 -> 40.4 | F16: {=$D16*SUM(IF('Raw Materials'!$B$2:$B$36=$B16,'Raw Materials'!$C$2:$C$36))} -> 145.44 | H16: {=$D16*SUM(IF('Raw Materials'!$B$2:$B$36=$B16,'Raw Materials'!$C$2:$C$36))/SUM(IF('Raw Materials'!$B$2:$B$36=$B16,'Raw Materials'!$D$2:$D$36))} -> 0.004545
B17: NIC | C17: 399 | D17: =C17 -> 399 | F17: {=$D17*SUM(IF('Raw Materials'!$B$2:$B$36=$B17,'Raw Materials'!$C$2:$C$36))} -> 199.5 | H17: {=$D17*SUM(IF('Raw Materials'!$B$2:$B$36=$B17,'Raw Materials'!$C$2:$C$36))/SUM(IF('Raw Materials'!$B$2:$B$36=$B17,'Raw Materials'!$D$2:$D$36))} -> 5.8676471e-05
B18: PRA | C18: 5.84 | D18: =C18 -> 5.84 | F18: {=$D18*SUM(IF('Raw Materials'!$B$2:$B$36=$B18,'Raw Materials'!$C$2:$C$36))} -> 18.688 | H18: {=$D18*SUM(IF('Raw Materials'!$B$2:$B$36=$B18,'Raw Materials'!$C$2:$C$36))/SUM(IF('Raw Materials'!$B$2:$B$36=$B18,'Raw Materials'!$D$2:$D$36))} -> 0.0020764444
B19: TER | C19: 1.14 | D19: =C19 -> 1.14 | F19: {=$D19*SUM(IF('Raw Materials'!$B$2:$B$36=$B19,'Raw Materials'!$C$2:$C$36))} -> 5.586 | H19: {=$D19*SUM(IF('Raw Materials'!$B$2:$B$36=$B19,'Raw Materials'!$C$2:$C$36))/SUM(IF('Raw Materials'!$B$2:$B$36=$B19,'Raw Materials'!$D$2:$D$36))} -> 0.011172
A20: Hydropower | B20: COP | C20: 1050 | D20: =C20 -> 1050 | E20: =SUM(D20:D22) -> 1280 | F20: {=$D20*SUM(IF('Raw Materials'!$B$2:$B$36=$B20,'Raw Materials'!$C$2:$C$36))} -> 105 | G20: =SUM(F20:F22) -> 360 | H20: {=$D20*SUM(IF('Raw Materials'!$B$2:$B$36=$B20,'Raw Materials'!$C$2:$C$36))/SUM(IF('Raw Materials'!$B$2:$B$36=$B20,'Raw Materials'!$D$2:$D$36))} -> 4.0384615e-06 | I20: =SUM(H20:H22) -> 2.0450226e-05
B21: MAN | C21: 200 | D21: =C21 -> 200 | F21: {=$D21*SUM(IF('Raw Materials'!$B$2:$B$36=$B21,'Raw Materials'!$C$2:$C$36))} -> 240 | H21: {=$D21*SUM(IF('Raw Materials'!$B$2:$B$36=$B21,'Raw Materials'!$C$2:$C$36))/SUM(IF('Raw Materials'!$B$2:$B$36=$B21,'Raw Materials'!$D$2:$D$36))} -> 1.2e-05
B22: NIC | C22: 30 | D22: =C22 -> 30 | F22: {=$D22*SUM(IF('Raw Materials'!$B$2:$B$36=$B22,'Raw Materials'!$C$2:$C$36))} -> 15 | H22: {=$D22*SUM(IF('Raw Materials'!$B$2:$B$36=$B22,'Raw Materials'!$C$2:$C$36))/SUM(IF('Raw Materials'!$B$2:$B$36=$B22,'Raw Materials'!$D$2:$D$36))} -> 4.4117647e-06
A23: Geothermal | B23: CHR | C23: 62000 | D23: =C23 -> 62000 | E23: =SUM(D23:D24) -> 182000 | F23: {=$D23*SUM(IF('Raw Materials'!$B$2:$B$36=$B23,'Raw Materials'!$C$2:$C$36))} -> 43400 | G23: =SUM(F23:F24) -> 103400 | H23: {=$D23*SUM(IF('Raw Materials'!$B$2:$B$36=$B23,'Raw Materials'!$C$2:$C$36))/SUM(IF('Raw Materials'!$B$2:$B$36=$B23,'Raw Materials'!$D$2:$D$36))} -> 0.001085 | I23: =SUM(H23:H24) -> 0.018732059
B24: NIC | C24: 120000 | D24: =C24 -> 120000 | F24: {=$D24*SUM(IF('Raw Materials'!$B$2:$B$36=$B24,'Raw Materials'!$C$2:$C$36))} -> 60000 | H24: {=$D24*SUM(IF('Raw Materials'!$B$2:$B$36=$B24,'Raw Materials'!$C$2:$C$36))/SUM(IF('Raw Materials'!$B$2:$B$36=$B24,'Raw Materials'!$D$2:$D$36))} -> 0.017647059
A25: Bioenergy | B25: COP | C25: 2270 | D25: =C25 -> 2270 | E25: =SUM(D25:D26) -> 2670 | F25: {=$D25*SUM(IF('Raw Materials'!$B$2:$B$36=$B25,'Raw Materials'!$C$2:$C$36))} -> 227 | G25: =SUM(F25:F26) -> 427 | H25: {=$D25*SUM(IF('Raw Materials'!$B$2:$B$36=$B25,'Raw Materials'!$C$2:$C$36))/SUM(IF('Raw Materials'!$B$2:$B$36=$B25,'Raw Materials'!$D$2:$D$36))} -> 8.7307692e-06 | I25: =SUM(H25:H26) -> 0.00091782168
B26: TIT | C26: 400 | D26: =C26 -> 400 | F26: {=$D26*SUM(IF('Raw Materials'!$B$2:$B$36=$B26,'Raw Materials'!$C$2:$C$36))} -> 200 | H26: {=$D26*SUM(IF('Raw Materials'!$B$2:$B$36=$B26,'Raw Materials'!$C$2:$C$36))/SUM(IF('Raw Materials'!$B$2:$B$36=$B26,'Raw Materials'!$D$2:$D$36))} -> 0.00090909091
A27: Coal | B27: CHR | C27: 308 | D27: =C27 -> 308 | E27: =SUM(D27:D31) -> 2447.3 | F27: {=$D27*SUM(IF('Raw Materials'!$B$2:$B$36=$B27,'Raw Materials'!$C$2:$C$36))} -> 215.6 | G27: =SUM(F27:F31) -> 1087.54 | H27: {=$D27*SUM(IF('Raw Materials'!$B$2:$B$36=$B27,'Raw Materials'!$C$2:$C$36))/SUM(IF('Raw Materials'!$B$2:$B$36=$B27,'Raw Materials'!$D$2:$D$36))} -> 5.39e-06 | I27: =SUM(H27:H31) -> 0.0018535516
B28: COB | C28: 202 | D28: =C28 -> 202 | F28: {=$D28*SUM(IF('Raw Materials'!$B$2:$B$36=$B28,'Raw Materials'!$C$2:$C$36))} -> 343.4 | H28: {=$D28*SUM(IF('Raw Materials'!$B$2:$B$36=$B28,'Raw Materials'!$C$2:$C$36))/SUM(IF('Raw Materials'!$B$2:$B$36=$B28,'Raw Materials'!$D$2:$D$36))} -> 0.0015609091
B29: COP | C29: 1150 | D29: =C29 -> 1150 | F29: {=$D29*SUM(IF('Raw Materials'!$B$2:$B$36=$B29,'Raw Materials'!$C$2:$C$36))} -> 115 | H29: {=$D29*SUM(IF('Raw Materials'!$B$2:$B$36=$B29,'Raw Materials'!$C$2:$C$36))/SUM(IF('Raw Materials'!$B$2:$B$36=$B29,'Raw Materials'!$D$2:$D$36))} -> 4.4230769e-06
B30: MOL | C30: 66.3 | D30: =C30 -> 66.3 | F30: {=$D30*SUM(IF('Raw Materials'!$B$2:$B$36=$B30,'Raw Materials'!$C$2:$C$36))} -> 53.04 | H30: {=$D30*SUM(IF('Raw Materials'!$B$2:$B$36=$B30,'Raw Materials'!$C$2:$C$36))/SUM(IF('Raw Materials'!$B$2:$B$36=$B30,'Raw Materials'!$D$2:$D$36))} -> 0.0001768
B31: NIC | C31: 721 | D31: =C31 -> 721 | F31: {=$D31*SUM(IF('Raw Materials'!$B$2:$B$36=$B31,'Raw Materials'!$C$2:$C$36))} -> 360.5 | H31: {=$D31*SUM(IF('Raw Materials'!$B$2:$B$36=$B31,'Raw Materials'!$C$2:$C$36))/SUM(IF('Raw Materials'!$B$2:$B$36=$B31,'Raw Materials'!$D$2:$D$36))} -> 0.00010602941
A32: Natural Gas & Oil | B32: CHR | C32: 48.3 | D32: =C32 -> 48.3 | E32: =SUM(D32:D34) -> 1164.1 | F32: {=$D32*SUM(IF('Raw Materials'!$B$2:$B$36=$B32,'Raw Materials'!$C$2:$C$36))} -> 33.81 | G32: =SUM(F32:F34) -> 151.71 | H32: {=$D32*SUM(IF('Raw Materials'!$B$2:$B$36=$B32,'Raw Materials'!$C$2:$C$36))/SUM(IF('Raw Materials'!$B$2:$B$36=$B32,'Raw Materials'!$D$2:$D$36))} -> 8.4525e-07 | I32: =SUM(H32:H34) -> 7.3995486e-06
B33: COP | C33: 1100 | D33: =C33 -> 1100 | F33: {=$D33*SUM(IF('Raw Materials'!$B$2:$B$36=$B33,'Raw Materials'!$C$2:$C$36))} -> 110 | H33: {=$D33*SUM(IF('Raw Materials'!$B$2:$B$36=$B33,'Raw Materials'!$C$2:$C$36))/SUM(IF('Raw Materials'!$B$2:$B$36=$B33,'Raw Materials'!$D$2:$D$36))} -> 4.2307692e-06
B34: NIC | C34: 15.8 | D34: =C34 -> 15.8 | F34: {=$D34*SUM(IF('Raw Materials'!$B$2:$B$36=$B34,'Raw Materials'!$C$2:$C$36))} -> 7.9 | H34: {=$D34*SUM(IF('Raw Materials'!$B$2:$B$36=$B34,'Raw Materials'!$C$2:$C$36))/SUM(IF('Raw Materials'!$B$2:$B$36=$B34,'Raw Materials'!$D$2:$D$36))} -> 2.3235294e-06
A35: Nuclear | B35: CER | C35: 4.05 | D35: =C35 -> 4.05 | E35: =SUM(D35:D59) -> 10313.231 | F35: {=$D35*SUM(IF('Raw Materials'!$B$2:$B$36=$B35,'Raw Materials'!$C$2:$C$36))} -> 16.2 | G35: =SUM(F35:F59) -> 6442.8943 | H35: {=$D35*SUM(IF('Raw Materials'!$B$2:$B$36=$B35,'Raw Materials'!$C$2:$C$36))/SUM(IF('Raw Materials'!$B$2:$B$36=$B35,'Raw Materials'!$D$2:$D$36))} -> 0.000108 | I35: =SUM(H35:H59) -> 0.0045077616
B36: CHR | C36: 4590 | D36: =C36 -> 4590 | F36: {=$D36*SUM(IF('Raw Materials'!$B$2:$B$36=$B36,'Raw Materials'!$C$2:$C$36))} -> 3213 | H36: {=$D36*SUM(IF('Raw Materials'!$B$2:$B$36=$B36,'Raw Materials'!$C$2:$C$36))/SUM(IF('Raw Materials'!$B$2:$B$36=$B36,'Raw Materials'!$D$2:$D$36))} -> 8.0325e-05
B37: COB | C37: 9 | D37: =C37 -> 9 | F37: {=$D37*SUM(IF('Raw Materials'!$B$2:$B$36=$B37,'Raw Materials'!$C$2:$C$36))} -> 15.3 | H37: {=$D37*SUM(IF('Raw Materials'!$B$2:$B$36=$B37,'Raw Materials'!$C$2:$C$36))/SUM(IF('Raw Materials'!$B$2:$B$36=$B37,'Raw Materials'!$D$2:$D$36))} -> 6.9545455e-05
B38: COP | C38: 1500 | D38: =C38 -> 1500 | F38: {=$D38*SUM(IF('Raw Materials'!$B$2:$B$36=$B38,'Raw Materials'!$C$2:$C$36))} -> 150 | H38: {=$D38*SUM(IF('Raw Materials'!$B$2:$B$36=$B38,'Raw Materials'!$C$2:$C$36))/SUM(IF('Raw Materials'!$B$2:$B$36=$B38,'Raw Materials'!$D$2:$D$36))} -> 5.7692308e-06
B39: DYS | C39: 0.000212 | D39: =C39 -> 0.000212 | F39: {=$D39*SUM(IF('Raw Materials'!$B$2:$B$36=$B39,'Raw Materials'!$C$2:$C$36))} -> 0.0011872 | H39: {=$D39*SUM(IF('Raw Materials'!$B$2:$B$36=$B39,'Raw Materials'!$C$2:$C$36))/SUM(IF('Raw Materials'!$B$2:$B$36=$B39,'Raw Materials'!$D$2:$D$36))} -> 4.7488e-07
B40: EUP | C40: 0.0163 | D40: =C40 -> 0.0163 | F40: {=$D40*SUM(IF('Raw Materials'!$B$2:$B$36=$B40,'Raw Materials'!$C$2:$C$36))} -> 0.09128 | H40: {=$D40*SUM(IF('Raw Materials'!$B$2:$B$36=$B40,'Raw Materials'!$C$2:$C$36))/SUM(IF('Raw Materials'!$B$2:$B$36=$B40,'Raw Materials'!$D$2:$D$36))} -> 0.00018256
...
